Workbook

Sheet Dashboard
A1: Amazon India Product Analysis Dashboard
A3: Pricing, discounts and customer ratings across 1,351 unique products | Source: Amazon India product dataset (Kaggle) | Built with Excel
A5: Total Products | E5: Avg Rating | I5: Avg Discount | M5: % Rated 4.0+ | Q5: Avg MRP (₹)
A6: =COUNTA(Data!$A$2:$A$1352) -> 1351 | E6: =AVERAGE(Data!$H$2:$H$1352) -> 4.0918519 | I6: =AVERAGE(Data!$G$2:$G$1352) -> 0.46685418 | M6: =COUNTIFS(Data!$H$2:$H$1352,">=4")/COUNT(Data!$H$2:$H$1352) -> 0.74814815 | Q6: =AVERAGE(Data!$E$2:$E$1352) -> 5691.1766

Sheet Data
A1: Product ID | B1: Product Name | C1: Main Category | D1: Sub Category | E1: Actual Price (₹) | F1: Discounted Price (₹) | G1: Discount % | H1: Rating | I1: Rating Count | J1: Discount Amount (₹) | K1: Discount Band | L1: Rating Band
A2: B07JW9H4J1 | B2: Wayona Nylon Braided USB to Lightning Fast Charging and Data Sync Cable Compatible for iPhone 13, 12,11, X, 8, 7, 6, 5, iPad Air, Pro, Mini (3 FT Pack of 1, Grey) | C2: Computers & Accessories | D2: Accessories & Peripherals | E2: 1099 | F2: 399 | G2: 0.64 | H2: 4.2 | I2: 24269 | J2: =E2-F2 -> 700 | K2: =IF(G2<0.2,"0-19%",IF(G2<0.4,"20-39%",IF(G2<0.6,"40-59%",IF(G2<0.8,"60-79%","80%+")))) -> 60-79% | L2: =IF(H2="","No rating",IF(H2<3.5,"Below 3.5",IF(H2<4,"3.5-3.9",IF(H2<4.5,"4.0-4.4","4.5+")))) -> 4.0-4.4
A3: B098NS6PVG | B3: Ambrane Unbreakable 60W / 3A Fast Charging 1.5m Braided Type C Cable for Smartphones, Tablets, Laptops & other Type C devices, PD Technology, 480Mbps Data Sync, Quick Charge 3.0 (RCT15A, Black) | C3: Computers & Accessories | D3: Accessories & Peripherals | E3: 349 | F3: 199 | G3: 0.43 | H3: 4 | I3: 43994 | J3: =E3-F3 -> 150 | K3: =IF(G3<0.2,"0-19%",IF(G3<0.4,"20-39%",IF(G3<0.6,"40-59%",IF(G3<0.8,"60-79%","80%+")))) -> 40-59% | L3: =IF(H3="","No rating",IF(H3<3.5,"Below 3.5",IF(H3<4,"3.5-3.9",IF(H3<4.5,"4.0-4.4","4.5+")))) -> 4.0-4.4
A4: B096MSW6CT | B4: Sounce Fast Phone Charging Cable & Data Sync USB Cable Compatible for iPhone 13, 12,11, X, 8, 7, 6, 5, iPad Air, Pro, Mini & iOS Devices | C4: Computers & Accessories | D4: Accessories & Peripherals | E4: 1899 | F4: 199 | G4: 0.9 | H4: 3.9 | I4: 7928 | J4: =E4-F4 -> 1700 | K4: =IF(G4<0.2,"0-19%",IF(G4<0.4,"20-39%",IF(G4<0.6,"40-59%",IF(G4<0.8,"60-79%","80%+")))) -> 80%+ | L4: =IF(H4="","No rating",IF(H4<3.5,"Below 3.5",IF(H4<4,"3.5-3.9",IF(H4<4.5,"4.0-4.4","4.5+")))) -> 3.5-3.9
A5: B08HDJ86NZ | B5: boAt Deuce USB 300 2 in 1 Type-C & Micro USB Stress Resistant, Tangle-Free, Sturdy Cable with 3A Fast Charging & 480mbps Data Transmission, 10000+ Bends Lifespan and Extended 1.5m Length(Martian Red) | C5: Computers & Accessories | D5: Accessories & Peripherals | E5: 699 | F5: 329 | G5: 0.53 | H5: 4.2 | I5: 94363 | J5: =E5-F5 -> 370 | K5: =IF(G5<0.2,"0-19%",IF(G5<0.4,"20-39%",IF(G5<0.6,"40-59%",IF(G5<0.8,"60-79%","80%+")))) -> 40-59% | L5: =IF(H5="","No rating",IF(H5<3.5,"Below 3.5",IF(H5<4,"3.5-3.9",IF(H5<4.5,"4.0-4.4","4.5+")))) -> 4.0-4.4
A6: B08CF3B7N1 | B6: Portronics Konnect L 1.2M Fast Charging 3A 8 Pin USB Cable with Charge & Sync Function for iPhone, iPad (Grey) | C6: Computers & Accessories | D6: Accessories & Peripherals | E6: 399 | F6: 154 | G6: 0.61 | H6: 4.2 | I6: 16905 | J6: =E6-F6 -> 245 | K6: =IF(G6<0.2,"0-19%",IF(G6<0.4,"20-39%",IF(G6<0.6,"40-59%",IF(G6<0.8,"60-79%","80%+")))) -> 60-79% | L6: =IF(H6="","No rating",IF(H6<3.5,"Below 3.5",IF(H6<4,"3.5-3.9",IF(H6<4.5,"4.0-4.4","4.5+")))) -> 4.0-4.4
A7: B08Y1TFSP6 | B7: pTron Solero TB301 3A Type-C Data and Fast Charging Cable, Made in India, 480Mbps Data Sync, Strong and Durable 1.5-Meter Nylon Braided USB Cable for Type-C Devices for Charging Adapter (Black) | C7: Computers & Accessories | D7: Accessories & Peripherals | E7: 1000 | F7: 149 | G7: 0.85 | H7: 3.9 | I7: 24871 | J7: =E7-F7 -> 851 | K7: =IF(G7<0.2,"0-19%",IF(G7<0.4,"20-39%",IF(G7<0.6,"40-59%",IF(G7<0.8,"60-79%","80%+")))) -> 80%+ | L7: =IF(H7="","No rating",IF(H7<3.5,"Below 3.5",IF(H7<4,"3.5-3.9",IF(H7<4.5,"4.0-4.4","4.5+")))) -> 3.5-3.9
A8: B08WRWPM22 | B8: boAt Micro USB 55 Tangle-free, Sturdy Micro USB Cable with 3A Fast Charging & 480mbps Data Transmission (Black) | C8: Computers & Accessories | D8: Accessories & Peripherals | E8: 499 | F8: 176.63 | G8: 0.65 | H8: 4.1 | I8: 15188 | J8: =E8-F8 -> 322.37 | K8: =IF(G8<0.2,"0-19%",IF(G8<0.4,"20-39%",IF(G8<0.6,"40-59%",IF(G8<0.8,"60-79%","80%+")))) -> 60-79% | L8: =IF(H8="","No rating",IF(H8<3.5,"Below 3.5",IF(H8<4,"3.5-3.9",IF(H8<4.5,"4.0-4.4","4.5+")))) -> 4.0-4.4
A9: B08DDRGWTJ | B9: MI Usb Type-C Cable Smartphone (Black) | C9: Computers & Accessories | D9: Accessories & Peripherals | E9: 299 | F9: 229 | G9: 0.23 | H9: 4.3 | I9: 30411 | J9: =E9-F9 -> 70 | K9: =IF(G9<0.2,"0-19%",IF(G9<0.4,"20-39%",IF(G9<0.6,"40-59%",IF(G9<0.8,"60-79%","80%+")))) -> 20-39% | L9: =IF(H9="","No rating",IF(H9<3.5,"Below 3.5",IF(H9<4,"3.5-3.9",IF(H9<4.5,"4.0-4.4","4.5+")))) -> 4.0-4.4
A10: B008IFXQFU | B10: TP-Link USB WiFi Adapter for PC(TL-WN725N), N150 Wireless Network Adapter for Desktop - Nano Size WiFi Dongle Compatible with Windows 11/10/7/8/8.1/XP/ Mac OS 10.9-10.15 Linux Kernel 2.6.18-4.4.3 | C10: Computers & Accessories | D10: Networking Devices | E10: 999 | F10: 499 | G10: 0.5 | H10: 4.2 | I10: 179691 | J10: =E10-F10 -> 500 | K10: =IF(G10<0.2,"0-19%",IF(G10<0.4,"20-39%",IF(G10<0.6,"40-59%",IF(G10<0.8,"60-79%","80%+")))) -> 40-59% | L10: =IF(H10="","No rating",IF(H10<3.5,"Below 3.5",IF(H10<4,"3.5-3.9",IF(H10<4.5,"4.0-4.4","4.5+")))) -> 4.0-4.4
A11: B082LZGK39 | B11: Ambrane Unbreakable 60W / 3A Fast Charging 1.5m Braided Micro USB Cable for Smartphones, Tablets, Laptops & Other Micro USB Devices, 480Mbps Data Sync, Quick Charge 3.0 (RCM15, Black) | C11: Computers & Accessories | D11: Accessories & Peripherals | E11: 299 | F11: 199 | G11: 0.33 | H11: 4 | I11: 43994 | J11: =E11-F11 -> 100 | K11: =IF(G11<0.2,"0-19%",IF(G11<0.4,"20-39%",IF(G11<0.6,"40-59%",IF(G11<0.8,"60-79%","80%+")))) -> 20-39% | L11: =IF(H11="","No rating",IF(H11<3.5,"Below 3.5",IF(H11<4,"3.5-3.9",IF(H11<4.5,"4.0-4.4","4.5+")))) -> 4.0-4.4
A12: B08CF3D7QR | B12: Portronics Konnect L POR-1081 Fast Charging 3A Type-C Cable 1.2Meter with Charge & Sync Function for All Type-C Devices (Grey) | C12: Computers & Accessories | D12: Accessories & Peripherals | E12: 339 | F12: 154 | G12: 0.55 | H12: 4.3 | I12: 13391 | J12: =E12-F12 -> 185 | K12: =IF(G12<0.2,"0-19%",IF(G12<0.4,"20-39%",IF(G12<0.6,"40-59%",IF(G12<0.8,"60-79%","80%+")))) -> 40-59% | L12: =IF(H12="","No rating",IF(H12<3.5,"Below 3.5",IF(H12<4,"3.5-3.9",IF(H12<4.5,"4.0-4.4","4.5+")))) -> 4.0-4.4
A13: B0789LZTCJ | B13: boAt Rugged v3 Extra Tough Unbreakable Braided Micro USB Cable 1.5 Meter (Black) | C13: Computers & Accessories | D13: Accessories & Peripherals | E13: 799 | F13: 299 | G13: 0.63 | H13: 4.2 | I13: 94363 | J13: =E13-F13 -> 500 | K13: =IF(G13<0.2,"0-19%",IF(G13<0.4,"20-39%",IF(G13<0.6,"40-59%",IF(G13<0.8,"60-79%","80%+")))) -> 60-79% | L13: =IF(H13="","No rating",IF(H13<3.5,"Below 3.5",IF(H13<4,"3.5-3.9",IF(H13<4.5,"4.0-4.4","4.5+")))) -> 4.0-4.4
... A283: B09PTT8DZF | B283: Lenovo USB A to Type-C Tangle-free Aramid fiber braided 1.2m cable with 4A Fast charging & 480 MBPS data transmission, certified 10000+ bend lifespan, Metallic Grey | C283: Computers & Accessories | D283: Accessories & Peripherals | E283: 670 | F283: 417.44 | G283: 0.38 | H283: 3.9 | I283: 523 | J283: =E283-F283 -> 252.56 | K283: =IF(G283<0.2,"0-19%",IF(G283<0.4,"20-39%",IF(G283<0.6,"40-59%",IF(G283<0.8,"60-79%","80%+")))) -> 20-39% | L283: =IF(H283="","No rating",IF(H283<3.5,"Below 3.5",IF(H283<4,"3.5-3.9",IF(H283<4.5,"4.0-4.4","4.5+")))) -> 3.5-3.9
A284: B0B94JPY2N | B284: Amazon Brand - Solimo 65W Fast Charging Braided Type C to C Data Cable | Suitable For All Supported Mobile Phones (1 Meter, Black) | C284: Computers & Accessories | D284: Accessories & Peripherals | E284: 999 | F284: 199 | G284: 0.8 | H284: 3 | J284: =E284-F284 -> 800 | K284: =IF(G284<0.2,"0-19%",IF(G284<0.4,"20-39%",IF(G284<0.6,"40-59%",IF(G284<0.8,"60-79%","80%+")))) -> 80%+ | L284: =IF(H284="","No rating",IF(H284<3.5,"Below 3.5",IF(H284<4,"3.5-3.9",IF(H284<4.5,"4.0-4.4","4.5+")))) -> Below 3.5
A285: B0B3XXSB1K | B285: LG 139 cm (55 inches) 4K Ultra HD Smart LED TV 55UQ7500PSF (Ceramic Black) | C285: Electronics | D285: Home Theater, TV & Video | E285: 79990 | F285: 47990 | G285: 0.4 | H285: 4.3 | I285: 1376 | J285: =E285-F285 -> 32000 | K285: =IF(G285<0.2,"0-19%",IF(G285<0.4,"20-39%",IF(G285<0.6,"40-59%",IF(G285<0.8,"60-79%","80%+")))) -> 40-59% | L285: =IF(H285="","No rating",IF(H285<3.5,"Below 3.5",IF(H285<4,"3.5-3.9",IF(H285<4.5,"4.0-4.4","4.5+")))) -> 4.0-4.4
A286: B08RZ12GKR | B286: Tata Sky Digital TV HD Setup Box Remote | C286: Electronics | D286: Home Theater, TV & Video | E286: 499 | F286: 215 | G286: 0.57 | H286: 3.5 | I286: 121 | J286: =E286-F286 -> 284 | K286: =IF(G286<0.2,"0-19%",IF(G286<0.4,"20-39%",IF(G286<0.6,"40-59%",IF(G286<0.8,"60-79%","80%+")))) -> 40-59% | L286: =IF(H286="","No rating",IF(H286<3.5,"Below 3.5",IF(H286<4,"3.5-3.9",IF(H286<4.5,"4.0-4.4","4.5+")))) -> 3.5-3.9
A287: B0B4T8RSJ1 | B287: pTron Solero T241 2.4A Type-C Data & Charging USB Cable, Made in India, 480Mbps Data Sync, Durable 1-Meter Long USB Cable for Smartphone, Type-C USB Devices (White) | C287: Computers & Accessories | D287: Accessories & Peripherals | E287: 800 | F287: 99 | G287: 0.88 | H287: 3.9 | I287: 1075 | J287: =E287-F287 -> 701 | K287: =IF(G287<0.2,"0-19%",IF(G287<0.4,"20-39%",IF(G287<0.6,"40-59%",IF(G287<0.8,"60-79%","80%+")))) -> 80%+ | L287: =IF(H287="","No rating",IF(H287<3.5,"Below 3.5",IF(H287<4,"3.5-3.9",IF(H287<4.5,"4.0-4.4","4.5+")))) -> 3.5-3.9
A288: B0B7B9V9QP | B288: VU 108 cm (43 inches) Premium Series Full HD Smart LED TV 43GA (Black) | C288: Electronics | D288: Home Theater, TV & Video | E288: 35000 | F288: 18999 | G288: 0.46 | H288: 4 | I288: 1001 | J288: =E288-F288 -> 16001 | K288: =IF(G288<0.2,"0-19%",IF(G288<0.4,"20-39%",IF(G288<0.6,"40-59%",IF(G288<0.8,"60-79%","80%+")))) -> 40-59% | L288: =IF(H288="","No rating",IF(H288<3.5,"Below 3.5",IF(H288<4,"3.5-3.9",IF(H288<4.5,"4.0-4.4","4.5+")))) -> 4.0-4.4
A289: B08XXVXP3J | B289: Storite Super Speed USB 3.0 Male to Male Cable for Hard Drive Enclosures, Laptop Cooling Pad, DVD Players(60cm,Black) | C289: Computers & Accessories | D289: Accessories & Peripherals | E289: 999 | F289: 249 | G289: 0.75 | H289: 4.3 | I289: 112 | J289: =E289-F289 -> 750 | K289: =IF(G289<0.2,"0-19%",IF(G289<0.4,"20-39%",IF(G289<0.6,"40-59%",IF(G289<0.8,"60-79%","80%+")))) -> 60-79% | L289: =IF(H289="","No rating",IF(H289<3.5,"Below 3.5",IF(H289<4,"3.5-3.9",IF(H289<4.5,"4.0-4.4","4.5+")))) -> 4.0-4.4
A290: B06XGWRKYT | B290: Kodak 80 cm (32 Inches) HD Ready LED TV Kodak 32HDX900S (Black) | C290: Electronics | D290: Home Theater, TV & Video | E290: 15999 | F290: 7999 | G290: 0.5 | H290: 3.8 | I290: 3022 | J290: =E290-F290 -> 8000 | K290: =IF(G290<0.2,"0-19%",IF(G290<0.4,"20-39%",IF(G290<0.6,"40-59%",IF(G290<0.8,"60-79%","80%+")))) -> 40-59% | L290: =IF(H290="","No rating",IF(H290<3.5,"Below 3.5",IF(H290<4,"3.5-3.9",IF(H290<4.5,"4.0-4.4","4.5+")))) -> 3.5-3.9
A291: B07CWDX49D | B291: AmazonBasics Double Braided Nylon USB Type-C to Type-C 2.0 Cable, Charging Adapter, Smartphone 6 feet, Dark Grey | C291: Computers & Accessories | D291: Accessories & Peripherals | E291: 1600 | F291: 649 | G291: 0.59 | H291: 4.3 | I291: 5451 | J291: =E291-F291 -> 951 | K291: =IF(G291<0.2,"0-19%",IF(G291<0.4,"20-39%",IF(G291<0.6,"40-59%",IF(G291<0.8,"60-79%","80%+")))) -> 40-59% | L291: =IF(H291="","No rating",IF(H291<3.5,"Below 3.5",IF(H291<4,"3.5-3.9",IF(H291<4.5,"4.0-4.4","4.5+")))) -> 4.0-4.4
A292: B09TY4MSH3 | B292: Firestick Remote | C292: Electronics | D292: Home Theater, TV & Video | E292: 2499 | F292: 1289 | G292: 0.48 | H292: 3.3 | I292: 73 | J292: =E292-F292 -> 1210 | K292: =IF(G292<0.2,"0-19%",IF(G292<0.4,"20-39%",IF(G292<0.6,"40-59%",IF(G292<0.8,"60-79%","80%+")))) -> 40-59% | L292: =IF(H292="","No rating",IF(H292<3.5,"Below 3.5",IF(H292<4,"3.5-3.9",IF(H292<4.5,"4.0-4.4","4.5+")))) -> Below 3.5
A293: B07RY2X9MP | B293: AmazonBasics 10.2 Gbps High-Speed 4K HDMI Cable with Braided Cord (10-Foot, Dark Grey) | C293: Electronics | D293: Home Theater, TV & Video | E293: 1500 | F293: 609 | G293: 0.59 | H293: 4.5 | I293: 1029 | J293: =E293-F293 -> 891 | K293: =IF(G293<0.2,"0-19%",IF(G293<0.4,"20-39%",IF(G293<0.6,"40-59%",IF(G293<0.8,"60-79%","80%+")))) -> 40-59% | L293: =IF(H293="","No rating",IF(H293<3.5,"Below 3.5",IF(H293<4,"3.5-3.9",IF(H293<4.5,"4.0-4.4","4.5+")))) -> 4.5+
A294: B0B2C5MJN6 | B294: Hisense 126 cm (50 inches) Bezelless Series 4K Ultra HD Smart LED Google TV 50A6H (Black) | C294: Electronics | D294: Home Theater, TV & Video | E294: 54990 | F294: 32990 | G294: 0.4 | H294: 4.1 | I294: 1555 | J294: =E294-F294 -> 22000 | K294: =IF(G294<0.2,"0-19%",IF(G294<0.4,"20-39%",IF(G294<0.6,"40-59%",IF(G294<0.8,"60-79%","80%+")))) -> 40-59% | L294: =IF(H294="","No rating",IF(H294<3.5,"Below 3.5",IF(H294<4,"3.5-3.9",IF(H294<4.5,"4.0-4.4","4.5+")))) -> 4.0-4.4
A295: B0BBMGLQDW | B295: Tuarso 8K HDMI 2.1 Cable 48Gbps , 1.5 Meter High-Speed Braided HDMI Cable ( 8K@60HZ、4K@120HZ、2K@240HZ ) HDMI 2.1 Cable Compatible with Monitors , Television , Laptops , Projectors , Game Consoles and more with HDMI Ports Device | C295: Electronics | D295: Home Theater, TV & Video | E295: 1999 | F295: 599 | G295: 0.7 | H295: 4.2 | I295: 47 | J295: =E295-F295 -> 1400 | K295: =IF(G295<0.2,"0-19%",IF(G295<0.4,"20-39%",IF(G295<0.6,"40-59%",IF(G295<0.8,"60-79%","80%+")))) -> 60-79% | L295: =IF(H295="","No rating",IF(H295<3.5,"Below 3.5",IF(H295<4,"3.5-3.9",IF(H295<4.5,"4.0-4.4","4.5+")))) -> 4.0-4.4
A296: B01LONQBDG | B296: AmazonBasics USB Type-C to Micro-B 2.0 Cable - 6 Inches (15.2 Centimeters) - White | C296: Computers & Accessories | D296: Accessories & Peripherals | E296: 899 | F296: 349 | G296: 0.61 | H296: 4.1 | I296: 14896 | J296: =E296-F296 -> 550 | K296: =IF(G296<0.2,"0-19%",IF(G296<0.4,"20-39%",IF(G296<0.6,"40-59%",IF(G296<0.8,"60-79%","80%+")))) -> 60-79% | L296: =IF(H296="","No rating",IF(H296<3.5,"Below 3.5",IF(H296<4,"3.5-3.9",IF(H296<4.5,"4.0-4.4","4.5+")))) -> 4.0-4.4
... A325: B08FD2VSD9 | B325: TCL 108 cm (43 inches) 4K Ultra HD Certified Android Smart LED TV 43P615 (Black) | C325: Electronics | D325: Home Theater, TV & Video | E325: 51990 | F325: 24990 | G325: 0.52 | H325: 4.2 | I325: 2951 | J325: =E325-F325 -> 27000 | K325: =IF(G325<0.2,"0-19%",IF(G325<0.4,"20-39%",IF(G325<0.6,"40-59%",IF(G325<0.8,"60-79%","80%+")))) -> 40-59% | L325: =IF(H325="","No rating",IF(H325<3.5,"Below 3.5",IF(H325<4,"3.5-3.9",IF(H325<4.5,"4.0-4.4","4.5+")))) -> 4.0-4.4
A326: B0BQRJ3C47 | B326: REDTECH USB-C to Lightning Cable 3.3FT, [Apple MFi Certified] Lightning to Type C Fast Charging Cord Compatible with iPhone 14/13/13 pro/Max/12/11/X/XS/XR/8, Supports Power Delivery - White | C326: Computers & Accessories | D326: Accessories & Peripherals | E326: 999 | F326: 249 | G326: 0.75 | H326: 5 | J326: =E326-F326 -> 750 | K326: =IF(G326<0.2,"0-19%",IF(G326<0.4,"20-39%",IF(G326<0.6,"40-59%",IF(G326<0.8,"60-79%","80%+")))) -> 60-79% | L326: =IF(H326="","No rating",IF(H326<3.5,"Below 3.5",IF(H326<4,"3.5-3.9",IF(H326<4.5,"4.0-4.4","4.5+")))) -> 4.5+
A327: B095JPKPH3 | B327: OnePlus 163.8 cm (65 inches) U Series 4K LED Smart Android TV 65U1S (Black) | C327: Electronics | D327: Home Theater, TV & Video | E327: 69999 | F327: 61999 | G327: 0.11 | H327: 4.1 | I327: 6753 | J327: =E327-F327 -> 8000 | K327: =IF(G327<0.2,"0-19%",IF(G327<0.4,"20-39%",IF(G327<0.6,"40-59%",IF(G327<0.8,"60-79%","80%+")))) -> 0-19% | L327: =IF(H327="","No rating",IF(H327<3.5,"Below 3.5",IF(H327<4,"3.5-3.9",IF(H327<4.5,"4.0-4.4","4.5+")))) -> 4.0-4.4
A328: B087JWLZ2K | B328: AmazonBasics 108 cm (43 inches) 4K Ultra HD Smart LED Fire TV AB43U20PS (Black) | C328: Electronics | D328: Home Theater, TV & Video | E328: 50000 | F328: 24499 | G328: 0.51 | H328: 3.9 | I328: 3518 | J328: =E328-F328 -> 25501 | K328: =IF(G328<0.2,"0-19%",IF(G328<0.4,"20-39%",IF(G328<0.6,"40-59%",IF(G328<0.8,"60-79%","80%+")))) -> 40-59% | L328: =IF(H328="","No rating",IF(H328<3.5,"Below 3.5",IF(H328<4,"3.5-3.9",IF(H328<4.5,"4.0-4.4","4.5+")))) -> 3.5-3.9
A329: B09DSXK8JX | B329: Kodak 80 cm (32 inches) HD Ready Certified Android Smart LED TV 32HDX7XPROBL (Black) | C329: Electronics | D329: Home Theater, TV & Video | E329: 19499 | F329: 10499 | G329: 0.46 | H329: 4.2 | I329: 1510 | J329: =E329-F329 -> 9000 | K329: =IF(G329<0.2,"0-19%",IF(G329<0.4,"20-39%",IF(G329<0.6,"40-59%",IF(G329<0.8,"60-79%","80%+")))) -> 40-59% | L329: =IF(H329="","No rating",IF(H329<3.5,"Below 3.5",IF(H329<4,"3.5-3.9",IF(H329<4.5,"4.0-4.4","4.5+")))) -> 4.0-4.4
A330: B08V9C4B1J | B330: Synqe Type C to Type C Short Fast Charging 60W Cable Compatible with Samsung Galaxy Z Fold3 5G, Z Flip3 5G, S22 5G, S22 Ultra, S21, S20, S20FE, A52, A73, A53 (0.25M, Black) | C330: Computers & Accessories | D330: Accessories & Peripherals | E330: 999 | F330: 349 | G330: 0.65 | H330: 4.3 | I330: 838 | J330: =E330-F330 -> 650 | K330: =IF(G330<0.2,"0-19%",IF(G330<0.4,"20-39%",IF(G330<0.6,"40-59%",IF(G330<0.8,"60-79%","80%+")))) -> 60-79% | L330: =IF(H330="","No rating",IF(H330<3.5,"Below 3.5",IF(H330<4,"3.5-3.9",IF(H330<4.5,"4.0-4.4","4.5+")))) -> 4.0-4.4
A331: B08PKBMJKS | B331: Airtel DigitalTV HD Setup Box Remote | C331: Electronics | D331: Home Theater, TV & Video | E331: 499 | F331: 197 | G331: 0.61 | H331: 3.8 | I331: 136 | J331: =E331-F331 -> 302 | K331: =IF(G331<0.2,"0-19%",IF(G331<0.4,"20-39%",IF(G331<0.6,"40-59%",IF(G331<0.8,"60-79%","80%+")))) -> 60-79% | L331: =IF(H331="","No rating",IF(H331<3.5,"Below 3.5",IF(H331<4,"3.5-3.9",IF(H331<4.5,"4.0-4.4","4.5+")))) -> 3.5-3.9
A332: B0B8VQ7KDS | B332: Airtel Digital TV HD Set Top Box with FTA Pack | Unlimited Entertainment + Recording Feature + Free Standard Installation (6 Months Pack) | C332: Electronics | D332: Home Theater, TV & Video | E332: 2499 | F332: 1299 | G332: 0.48 | H332: 4.3 | I332: 301 | J332: =E332-F332 -> 1200 | K332: =IF(G332<0.2,"0-19%",IF(G332<0.4,"20-39%",IF(G332<0.6,"40-59%",IF(G332<0.8,"60-79%","80%+")))) -> 40-59% | L332: =IF(H332="","No rating",IF(H332<3.5,"Below 3.5",IF(H332<4,"3.5-3.9",IF(H332<4.5,"4.0-4.4","4.5+")))) -> 4.0-4.4
A333: B086JTMRYL | B333: ESR USB C to Lightning Cable, 10 ft (3 m), MFi-Certified, Braided Nylon Power Delivery Fast Charging for iPhone 14/14 Plus/14 Pro/14 Pro Max, iPhone 13/12/11/X/8 Series, Use with Type-C Chargers, Black | C333: Computers & Accessories | D333: Accessories & Peripherals | E333: 1899 | F333: 1519 | G333: 0.2 | H333: 4.4 | I333: 19763 | J333: =E333-F333 -> 380 | K333: =IF(G333<0.2,"0-19%",IF(G333<0.4,"20-39%",IF(G333<0.6,"40-59%",IF(G333<0.8,"60-79%","80%+")))) -> 20-39% | L333: =IF(H333="","No rating",IF(H333<3.5,"Below 3.5",IF(H333<4,"3.5-3.9",IF(H333<4.5,"4.0-4.4","4.5+")))) -> 4.0-4.4
A334: B09RWQ7YR6 | B334: MI 138.8 cm (55 inches) 5X Series 4K Ultra HD LED Smart Android TV L55M6-ES (Grey) | C334: Electronics | D334: Home Theater, TV & Video | E334: 69999 | F334: 46999 | G334: 0.33 | H334: 4.3 | I334: 21252 | J334: =E334-F334 -> 23000 | K334: =IF(G334<0.2,"0-19%",IF(G334<0.4,"20-39%",IF(G334<0.6,"40-59%",IF(G334<0.8,"60-79%","80%+")))) -> 20-39% | L334: =IF(H334="","No rating",IF(H334<3.5,"Below 3.5",IF(H334<4,"3.5-3.9",IF(H334<4.5,"4.0-4.4","4.5+")))) -> 4.0-4.4
A335: B00OFM6PEO | B335: Storite USB Extension Cable USB 3.0 Male to Female Extension Cable High Speed 5GBps Extension Cable Data Transfer for Keyboard, Mouse, Flash Drive, Hard Drive, Printer and More- 1.5M - Blue | C335: Computers & Accessories | D335: Accessories & Peripherals | E335: 799 | F335: 299 | G335: 0.63 | H335: 4.3 | I335: 1902 | J335: =E335-F335 -> 500 | K335: =IF(G335<0.2,"0-19%",IF(G335<0.4,"20-39%",IF(G335<0.6,"40-59%",IF(G335<0.8,"60-79%","80%+")))) -> 60-79% | L335: =IF(H335="","No rating",IF(H335<3.5,"Below 3.5",IF(H335<4,"3.5-3.9",IF(H335<4.5,"4.0-4.4","4.5+")))) -> 4.0-4.4
A336: B0BF57RN3K | B336: Fire-Boltt Ninja Call Pro Plus 1.83" Smart Watch with Bluetooth Calling, AI Voice Assistance, 100 Sports Modes IP67 Rating, 240*280 Pixel High Resolution | C336: Electronics | D336: Wearable Technology | E336: 19999 | F336: 1799 | G336: 0.91 | H336: 4.2 | I336: 13937 | J336: =E336-F336 -> 18200 | K336: =IF(G336<0.2,"0-19%",IF(G336<0.4,"20-39%",IF(G336<0.6,"40-59%",IF(G336<0.8,"60-79%","80%+")))) -> 80%+ | L336: =IF(H336="","No rating",IF(H336<3.5,"Below 3.5",IF(H336<4,"3.5-3.9",IF(H336<4.5,"4.0-4.4","4.5+")))) -> 4.0-4.4
A337: B0B3RRWSF6 | B337: Fire-Boltt Phoenix Smart Watch with Bluetooth Calling 1.3",120+ Sports Modes, 240*240 PX High Res with SpO2, Heart Rate Monitoring & IP67 Rating | C337: Electronics | D337: Wearable Technology | E337: 9999 | F337: 1998 | G337: 0.8 | H337: 4.3 | I337: 27696 | J337: =E337-F337 -> 8001 | K337: =IF(G337<0.2,"0-19%",IF(G337<0.4,"20-39%",IF(G337<0.6,"40-59%",IF(G337<0.8,"60-79%","80%+")))) -> 80%+ | L337: =IF(H337="","No rating",IF(H337<3.5,"Below 3.5",IF(H337<4,"3.5-3.9",IF(H337<4.5,"4.0-4.4","4.5+")))) -> 4.0-4.4
...

Sheet Analysis
A1: 1. Products by Main Category
A2: Main Category | B2: Products | C2: Avg Discount % | D2: Avg Rating | E2: % Rated 4.0+
A3: Electronics | B3: =COUNTIFS(Data!$C$2:$C$1352,A3) -> 490 | C3: =AVERAGEIFS(Data!$G$2:$G$1352,Data!$C$2:$C$1352,A3) -> 0.49906122 | D3: =AVERAGEIFS(Data!$H$2:$H$1352,Data!$C$2:$C$1352,A3) -> 4.0777551 | E3: =COUNTIFS(Data!$C$2:$C$1352,A3,Data!$H$2:$H$1352,">=4")/COUNTIFS(Data!$C$2:$C$1352,A3,Data!$H$2:$H$1352,">0") -> 0.73877551
A4: Home & Kitchen | B4: =COUNTIFS(Data!$C$2:$C$1352,A4) -> 448 | C4: =AVERAGEIFS(Data!$G$2:$G$1352,Data!$C$2:$C$1352,A4) -> 0.40120536 | D4: =AVERAGEIFS(Data!$H$2:$H$1352,Data!$C$2:$C$1352,A4) -> 4.0407159 | E4: =COUNTIFS(Data!$C$2:$C$1352,A4,Data!$H$2:$H$1352,">=4")/COUNTIFS(Data!$C$2:$C$1352,A4,Data!$H$2:$H$1352,">0") -> 0.67785235
A5: Computers & Accessories | B5: =COUNTIFS(Data!$C$2:$C$1352,A5) -> 375 | C5: =AVERAGEIFS(Data!$G$2:$G$1352,Data!$C$2:$C$1352,A5) -> 0.53224 | D5: =AVERAGEIFS(Data!$H$2:$H$1352,Data!$C$2:$C$1352,A5) -> 4.1538667 | E5: =COUNTIFS(Data!$C$2:$C$1352,A5,Data!$H$2:$H$1352,">=4")/COUNTIFS(Data!$C$2:$C$1352,A5,Data!$H$2:$H$1352,">0") -> 0.824
A6: Office Products | B6: =COUNTIFS(Data!$C$2:$C$1352,A6) -> 31 | C6: =AVERAGEIFS(Data!$G$2:$G$1352,Data!$C$2:$C$1352,A6) -> 0.12354839 | D6: =AVERAGEIFS(Data!$H$2:$H$1352,Data!$C$2:$C$1352,A6) -> 4.3096774 | E6: =COUNTIFS(Data!$C$2:$C$1352,A6,Data!$H$2:$H$1352,">=4")/COUNTIFS(Data!$C$2:$C$1352,A6,Data!$H$2:$H$1352,">0") -> 1
A7: Other | B7: =COUNTIFS(Data!$C$2:$C$1352,A7) -> 7 | C7: =AVERAGEIFS(Data!$G$2:$G$1352,Data!$C$2:$C$1352,A7) -> 0.43142857 | D7: =AVERAGEIFS(Data!$H$2:$H$1352,Data!$C$2:$C$1352,A7) -> 4.0571429 | E7: =COUNTIFS(Data!$C$2:$C$1352,A7,Data!$H$2:$H$1352,">=4")/COUNTIFS(Data!$C$2:$C$1352,A7,Data!$H$2:$H$1352,">0") -> 0.71428571
A10: 2. Top 10 Sub-Categories (by product count)
A11: Sub Category | B11: Products | C11: Avg Discount % | D11: Avg Rating
A12: Kitchen & Home Appliances | B12: =COUNTIFS(Data!$D$2:$D$1352,A12) -> 308 | C12: =AVERAGEIFS(Data!$G$2:$G$1352,Data!$D$2:$D$1352,A12) -> 0.40256494 | D12: =AVERAGEIFS(Data!$H$2:$H$1352,Data!$D$2:$D$1352,A12) -> 4.0534202
A13: Accessories & Peripherals | B13: =COUNTIFS(Data!$D$2:$D$1352,A13) -> 307 | C13: =AVERAGEIFS(Data!$G$2:$G$1352,Data!$D$2:$D$1352,A13) -> 0.55442997 | D13: =AVERAGEIFS(Data!$H$2:$H$1352,Data!$D$2:$D$1352,A13) -> 4.1449511
A14: Home Theater, TV & Video | B14: =COUNTIFS(Data!$D$2:$D$1352,A14) -> 156 | C14: =AVERAGEIFS(Data!$G$2:$G$1352,Data!$D$2:$D$1352,A14) -> 0.49391026 | D14: =AVERAGEIFS(Data!$H$2:$H$1352,Data!$D$2:$D$1352,A14) -> 4.0711538
A15: Mobiles & Accessories | B15: =COUNTIFS(Data!$D$2:$D$1352,A15) -> 151 | C15: =AVERAGEIFS(Data!$G$2:$G$1352,Data!$D$2:$D$1352,A15) -> 0.41470199 | D15: =AVERAGEIFS(Data!$H$2:$H$1352,Data!$D$2:$D$1352,A15) -> 4.1258278
A16: Heating, Cooling & Air Quality | B16: =COUNTIFS(Data!$D$2:$D$1352,A16) -> 116 | C16: =AVERAGEIFS(Data!$G$2:$G$1352,Data!$D$2:$D$1352,A16) -> 0.40681034 | D16: =AVERAGEIFS(Data!$H$2:$H$1352,Data!$D$2:$D$1352,A16) -> 3.9905172
A17: Headphones, Earbuds & Accessories | B17: =COUNTIFS(Data!$D$2:$D$1352,A17) -> 63 | C17: =AVERAGEIFS(Data!$G$2:$G$1352,Data!$D$2:$D$1352,A17) -> 0.59492063 | D17: =AVERAGEIFS(Data!$H$2:$H$1352,Data!$D$2:$D$1352,A17) -> 3.9206349
A18: Wearable Technology | B18: =COUNTIFS(Data!$D$2:$D$1352,A18) -> 62 | C18: =AVERAGEIFS(Data!$G$2:$G$1352,Data!$D$2:$D$1352,A18) -> 0.69677419 | D18: =AVERAGEIFS(Data!$H$2:$H$1352,Data!$D$2:$D$1352,A18) -> 4.0080645
A19: Networking Devices | B19: =COUNTIFS(Data!$D$2:$D$1352,A19) -> 30 | C19: =AVERAGEIFS(Data!$G$2:$G$1352,Data!$D$2:$D$1352,A19) -> 0.472 | D19: =AVERAGEIFS(Data!$H$2:$H$1352,Data!$D$2:$D$1352,A19) -> 4.1633333
A20: Office Paper Products | B20: =COUNTIFS(Data!$D$2:$D$1352,A20) -> 27 | C20: =AVERAGEIFS(Data!$G$2:$G$1352,Data!$D$2:$D$1352,A20) -> 0.14 | D20: =AVERAGEIFS(Data!$H$2:$H$1352,Data!$D$2:$D$1352,A20) -> 4.2888889
A21: External Devices & Data Storage | B21: =COUNTIFS(Data!$D$2:$D$1352,A21) -> 18 | C21: =AVERAGEIFS(Data!$G$2:$G$1352,Data!$D$2:$D$1352,A21) -> 0.46888889 | D21: =AVERAGEIFS(Data!$H$2:$H$1352,Data!$D$2:$D$1352,A21) -> 4.3166667
A24: 3. Discount Band Analysis
A25: Discount Band | B25: Products | C25: Avg Rating | D25: Avg Discounted Price (₹)
A26: 0-19% | B26: =COUNTIFS(Data!$K$2:$K$1352,A26) -> 162 | C26: =AVERAGEIFS(Data!$H$2:$H$1352,Data!$K$2:$K$1352,A26) -> 4.1639752 | D26: =AVERAGEIFS(Data!$F$2:$F$1352,Data!$K$2:$K$1352,A26) -> 3978.6852
A27: 20-39% | B27: =COUNTIFS(Data!$K$2:$K$1352,A27) -> 316 | C27: =AVERAGEIFS(Data!$H$2:$H$1352,Data!$K$2:$K$1352,A27) -> 4.1338608 | D27: =AVERAGEIFS(Data!$F$2:$F$1352,Data!$K$2:$K$1352,A27) -> 6629.1738
A28: 40-59% | B28: =COUNTIFS(Data!$K$2:$K$1352,A28) -> 449 | C28: =AVERAGEIFS(Data!$H$2:$H$1352,Data!$K$2:$K$1352,A28) -> 4.0815145 | D28: =AVERAGEIFS(Data!$F$2:$F$1352,Data!$K$2:$K$1352,A28) -> 2976.6867
A29: 60-79% | B29: =COUNTIFS(Data!$K$2:$K$1352,A29) -> 343 | C29: =AVERAGEIFS(Data!$H$2:$H$1352,Data!$K$2:$K$1352,A29) -> 4.0504373 | D29: =AVERAGEIFS(Data!$F$2:$F$1352,Data!$K$2:$K$1352,A29) -> 981.41087
A30: 80%+ | B30: =COUNTIFS(Data!$K$2:$K$1352,A30) -> 81 | C30: =AVERAGEIFS(Data!$H$2:$H$1352,Data!$K$2:$K$1352,A30) -> 4.017284 | D30: =AVERAGEIFS(Data!$F$2:$F$1352,Data!$K$2:$K$1352,A30) -> 645.24691
A33: 4. Rating Distribution
A34: Rating Band | B34: Products | C34: % of Products
A35: Below 3.5 | B35: =COUNTIFS(Data!$L$2:$L$1352,A35) -> 41 | C35: =B35/SUM($B$35:$B$38) -> 0.03037037
A36: 3.5-3.9 | B36: =COUNTIFS(Data!$L$2:$L$1352,A36) -> 299 | C36: =B36/SUM($B$35:$B$38) -> 0.22148148
A37: 4.0-4.4 | B37: =COUNTIFS(Data!$L$2:$L$1352,A37) -> 914 | C37: =B37/SUM($B$35:$B$38) -> 0.67703704
A38: 4.5+ | B38: =COUNTIFS(Data!$L$2:$L$1352,A38) -> 96 | C38: =B38/SUM($B$35:$B$38) -> 0.071111111
A41: 5. Top 10 Most-Reviewed Products (one per unique review count; colour/size variants share counts)
A42: Product ID | B42: Product (short) | C42: Reviews | D42: Rating | E42: Discount %
A43: B07KSMBL2H | B43: =LEFT(INDEX(Data!$B$2:$B$1352,MATCH(A43,Data!$A$2:$A$1352,0)),45) -> AmazonBasics Flexible Premium HDMI Cable (Bla | C43: =INDEX(Data!$I$2:$I$1352,MATCH(A43,Data!$A$2:$A$1352,0)) -> 426973 | D43: =INDEX(Data!$H$2:$H$1352,MATCH(A43,Data!$A$2:$A$1352,0)) -> 4.4 | E43: =INDEX(Data!$G$2:$G$1352,MATCH(A43,Data!$A$2:$A$1352,0)) -> 0.69
A44: B07GQD4K6L | B44: =LEFT(INDEX(Data!$B$2:$B$1352,MATCH(A44,Data!$A$2:$A$1352,0)),45) -> boAt Bassheads 100 in Ear Wired Earphones wit | C44: =INDEX(Data!$I$2:$I$1352,MATCH(A44,Data!$A$2:$A$1352,0)) -> 363713 | D44: =INDEX(Data!$H$2:$H$1352,MATCH(A44,Data!$A$2:$A$1352,0)) -> 4.1 | E44: =INDEX(Data!$G$2:$G$1352,MATCH(A44,Data!$A$2:$A$1352,0)) -> 0.62
A45: B071Z8M4KX | B45: =LEFT(INDEX(Data!$B$2:$B$1352,MATCH(A45,Data!$A$2:$A$1352,0)),45) -> boAt BassHeads 100 in-Ear Wired Headphones wi | C45: =INDEX(Data!$I$2:$I$1352,MATCH(A45,Data!$A$2:$A$1352,0)) -> 363711 | D45: =INDEX(Data!$H$2:$H$1352,MATCH(A45,Data!$A$2:$A$1352,0)) -> 4.1 | E45: =INDEX(Data!$G$2:$G$1352,MATCH(A45,Data!$A$2:$A$1352,0)) -> 0.63
A46: B09GFPVD9Y | B46: =LEFT(INDEX(Data!$B$2:$B$1352,MATCH(A46,Data!$A$2:$A$1352,0)),45) -> Redmi 9 Activ (Carbon Black, 4GB RAM, 64GB St | C46: =INDEX(Data!$I$2:$I$1352,MATCH(A46,Data!$A$2:$A$1352,0)) -> 313836 | D46: =INDEX(Data!$H$2:$H$1352,MATCH(A46,Data!$A$2:$A$1352,0)) -> 4.1 | E46: =INDEX(Data!$G$2:$G$1352,MATCH(A46,Data!$A$2:$A$1352,0)) -> 0.23
A47: B09GFM8CGS | B47: =LEFT(INDEX(Data!$B$2:$B$1352,MATCH(A47,Data!$A$2:$A$1352,0)),45) -> Redmi 9A Sport (Carbon Black, 2GB RAM, 32GB S | C47: =INDEX(Data!$I$2:$I$1352,MATCH(A47,Data!$A$2:$A$1352,0)) -> 313832 | D47: =INDEX(Data!$H$2:$H$1352,MATCH(A47,Data!$A$2:$A$1352,0)) -> 4.1 | E47: =INDEX(Data!$G$2:$G$1352,MATCH(A47,Data!$A$2:$A$1352,0)) -> 0.19
A48: B01MF8MB65 | B48: =LEFT(INDEX(Data!$B$2:$B$1352,MATCH(A48,Data!$A$2:$A$1352,0)),45) -> boAt Bassheads 225 in Ear Wired Earphones wit | C48: =INDEX(Data!$I$2:$I$1352,MATCH(A48,Data!$A$2:$A$1352,0)) -> 273189 | D48: =INDEX(Data!$H$2:$H$1352,MATCH(A48,Data!$A$2:$A$1352,0)) -> 4.1 | E48: =INDEX(Data!$G$2:$G$1352,MATCH(A48,Data!$A$2:$A$1352,0)) -> 0.3
...

Sheet Cleaning Log
A1: Step | B1: What was done | C1: Rows affected
A2: 1 | B2: Loaded raw CSV (amazon.csv) | C2: 1465
A3: 2 | B3: Removed duplicate Product IDs (kept first) | C3: 114
A4: 3 | B4: Removed ₹ symbol and commas from price columns, converted to numbers | C4: all
A5: 4 | B5: Converted Discount % from text ("64%") to a number (0.64) | C5: all
A6: 5 | B6: Rating had one invalid value ("|"): set to blank so it is excluded from averages | C6: 1
A7: 6 | B7: Rating Count had missing values: left blank, excluded from totals | C7: 2
A8: 7 | B8: Split category path into Main Category and Sub Category; grouped 5 tiny categories into "Other" | C8: all
A9: 8 | B9: Dropped columns not needed for this analysis (review text, user IDs, image and product links) | C9: -
A10: 9 | B10: Added helper columns with formulas: Discount Amount, Discount Band, Rating Band | C10: all
A11: 10 | B11: Final clean row count | C11: 1351
B13: Note: this dataset has no dates or units-sold column, so the analysis covers pricing, discounts and ratings, not sales revenue or trends.
